Workbook

Sheet renta
A1: Ressource | B1: - | C1: index | D1: rapport | E1: min/item | F1: prix man | G1: prix atuo | H1: coin/earth | I1: coin/precédent | J1: gain de l'usine coin/h | K1: gain/kpow | O1: pool
A2: EARTH | B2: EARTH | C2: =MATCH(B2, data!A:A, 0) -> #N/A | D2: 1 | E2: =(60+41)/50500 -> 0.002 | F2: =0.0041 -> 0.0041 | G2: =IFERROR(getCoinPrice($O2), $F2) -> 0.0041 | H2: =G2 -> 0.0041 | I2: =H2 -> 0.0041 | J2: =G2/E2+60 -> 62.05 | O2: 0xc356cd52364541379ad4d31a889b7031e758220a
A3: WATER | B3: WATER | C3: 0 | D3: =152/30 -> 5.0666667 | E3: =60/12 -> 5 | F3: 3.06 | G3: =IFERROR(getCoinPrice($O3), $F3) -> 3.06 | H3: =G3 -> 3.06 | I3: 0.46 | J3: 0 | O3: 0xe9c0995144a199241a5c46ccb7e7cd439af3ac75
A4: FIRE | B4: FIRE | C4: 0 | D4: 0 | E4: 0 | F4: 9.7 | G4: =IFERROR(getCoinPrice($O4), $F4) -> 9.7 | O4: 0xe973dc221bb031010ec673105ed8b04c9e713b9d
A5: MUD | B5: MUD_17 | C5: =MATCH(B5, data!A:A, 0) -> 18 | D5: =INDIRECT("'data'!G" & C5)/INDIRECT("'data'!B" & C5) -> 2.85 | E5: =INDIRECT("'data'!C" & C5)/INDIRECT("'data'!B" & C5)/2*24*60 -> 0.0070262919 | F5: 0.011 | G5: =IFERROR(getCoinPrice($O5), $F5) -> 0.011545385 | H5: =D2*D5*$G$2 -> 0.011685 | I5: =G2*D5 -> 0.011685 | J5: =INDIRECT("'data'!E" & C5) -> -3.6569761 | O5: 0xb287ea5a5cd4f2b74571e30fdec96241aa5163d9
A6: CLAY | B6: CLAY_16 | C6: =MATCH(B6, data!A:A, 0) -> 68 | D6: =INDIRECT("'data'!G" & C6)/INDIRECT("'data'!B" & C6) -> 9.5 | E6: =INDIRECT("'data'!C" & C6)/INDIRECT("'data'!B" & C6)/2*24*60 -> 0.033783784 | F6: 0.12 | G6: =IFERROR(getCoinPrice($O6), $F6) -> 0.12 | H6: =H5*D6 -> 0.1110075 | I6: =G5*D6 -> 0.10968116 | J6: =INDIRECT("'data'!E" & C6) -> 12.998265 | O6: 0x8b1a1b7b43a53904b0a05406c13399079e553501
A7: SAND | B7: SAND_11 | C7: =MATCH(B7, data!A:A, 0) -> 104 | D7: =INDIRECT("'data'!G" & C7)/INDIRECT("'data'!B" & C7) -> 2.85 | E7: =INDIRECT("'data'!C" & C7)/INDIRECT("'data'!B" & C7)/2*24*60 -> 0.12448718 | F7: 0.33 | G7: =IFERROR(getCoinPrice($O7), $F7) -> 0.31176929 | H7: =H6*D7 -> 0.31637138 | I7: =G6*D7 -> 0.342 | J7: =INDIRECT("'data'!E" & C7) -> -18.327158 | O7: 0x6d8839a585f7877a5e218a217c07334980f04a4a
A8: COPPER | B8: COPPER_6 | C8: =MATCH(B8, data!A:A, 0) -> 135 | D8: =INDIRECT("'data'!G" & C8)/INDIRECT("'data'!B" & C8) -> 28.5 | E8: =INDIRECT("'data'!C" & C8)/INDIRECT("'data'!B" & C8)/2*24*60 -> 5.825463 | F8: 8.33 | G8: =F8 -> 8.33 | H8: =H7*D8 -> 9.0165842 | I8: =G7*D8 -> 8.8854249 | J8: =INDIRECT("'data'!E" & C8) -> -7.8655541 | O8: 0xe9e419dbe8e0e056bb91989eb10f5fa62a0cb702
A9: STEEL | B9: STEEL_8 | C9: =MATCH(B9, data!A:A, 0) -> 293 | D9: =INDIRECT("'data'!G" & C9)/INDIRECT("'data'!B" & C9) -> 4.161 | E9: =INDIRECT("'data'!C" & C9)/INDIRECT("'data'!B" & C9)/2*24*60 -> 280 | F9: 37 | G9: =IFERROR(getCoinPrice($O9), $F9) -> 37 | H9: =H8*D9 -> 37.518007 | I9: =G8*D9 -> 34.66113 | J9: =INDIRECT("'data'!E" & C9) -> 0.42113128 | K9: =INDIRECT("'data'!W" & C9) -> 0.282774 | L9: screen1 | O9: 0x70c063f17dacb35e4b3df06c8f36020416a44a3c
A10: SCREWS | B10: SCREWS_7 | C10: =MATCH(B10, data!A:A, 0) -> 403 | D10: =INDIRECT("'data'!G" & C10)/INDIRECT("'data'!B" & C10) -> 2.7075 | E10: =INDIRECT("'data'!C" & C10)/INDIRECT("'data'!B" & C10)/2*24*60 -> 450 | F10: 113 | G10: =IFERROR(getCoinPrice($O10), $F10) -> 132.68215 | H10: =H9*D10 -> 101.58 | I10: =G9*D10 -> 100.1775 | J10: =INDIRECT("'data'!E" & C10) -> 5.9153534 | K10: =INDIRECT("'data'!W" & C10) -> 1.167504 | L10: =J2+3*J9+2*J10 -> 75.144101 | O10: 0x0016c4c602cc1a96a9d35fe133a7e374d3cdc26d
A11: SEAWATER | B11: SEAWATER_30 | C11: =MATCH(B11, data!A:A, 0) -> 190 | D11: =INDIRECT("'data'!G" & C11)/INDIRECT("'data'!B" & C11) -> 5.0666667 | E11: =INDIRECT("'data'!C" & C11)/INDIRECT("'data'!B" & C11)/2*24*60 -> 8 | F11: 18.3 | G11: =IFERROR(getCoinPrice($O11), $F11) -> 18.233974 | H11: =H3*D11 -> 15.504 | I11: =G3*D11 -> 15.504 | J11: =INDIRECT("'data'!E" & C11) -> 25.072222 | K11: =INDIRECT("'data'!W" & C11) -> 3.7902075 | L11: middle | O11: 0xd1d6bb059c97295f7437ad423111047cbcddf4c6
A12: ALGAE | B12: ALGAE_20 | C12: =MATCH(B12, data!A:A, 0) -> 242 | D12: =INDIRECT("'data'!G" & C12)/INDIRECT("'data'!B" & C12) -> 3.3041 | E12: =INDIRECT("'data'!C" & C12)/INDIRECT("'data'!B" & C12)/2*24*60 -> 24 | F12: 71 | G12: =IFERROR(getCoinPrice($O12), $F12) -> 71 | H12: =H11*D12 -> 51.226766 | I12: =G11*D12 -> 60.246873 | J12: =INDIRECT("'data'!E" & C12) -> 32.994617 | K12: =INDIRECT("'data'!W" & C12) -> 2.1125005 | L12: water | O12: 0xe63f8cefea9a17a259bb3b375929bd10d5e1cdfa
A13: OXYGEN | B13: OXYGEN_20 | C13: =MATCH(B13, data!A:A, 0) -> 326 | D13: =INDIRECT("'data'!G" & C13)/INDIRECT("'data'!B" & C13) -> 2.4779167 | E13: =INDIRECT("'data'!C" & C13)/INDIRECT("'data'!B" & C13)/2*24*60 -> 40 | F13: 208 | G13: =IFERROR(getCoinPrice($O13), $F13) -> 208 | H13: =H12*D13 -> 126.93566 | I13: =G12*D13 -> 175.93208 | J13: =INDIRECT("'data'!E" & C13) -> 56.019606 | K13: =INDIRECT("'data'!W" & C13) -> 1.6283586 | L13: =2*J11+2*#REF!+3*J12+3*J13+3*J14+2*J15+J16 -> #REF! | O13: 0x4343846ebe54dcd40ba572275640230d533296e5
A14: GAS | B14: GAS_15 | C14: =MATCH(B14, data!A:A, 0) -> 363 | D14: =INDIRECT("'data'!G" & C14)/INDIRECT("'data'!B" & C14) -> 1.653 | E14: =INDIRECT("'data'!C" & C14)/INDIRECT("'data'!B" & C14)/2*24*60 -> 80 | F14: 386 | G14: =IFERROR(getCoinPrice($O14), $F14) -> 386 | H14: =H13*D14 -> 209.82464 | I14: =G13*D14 -> 343.824 | J14: =INDIRECT("'data'!E" & C14) -> 30.493125 | K14: =INDIRECT("'data'!W" & C14) -> 0.70708696 | L14: Lava | O14: 0x4782e36bbe6e9abca5357d3e43a090fa772de71b
A15: FUEL | B15: FUEL_15 | C15: =MATCH(B15, data!A:A, 0) -> 427 | D15: =INDIRECT("'data'!G" & C15)/INDIRECT("'data'!B" & C15) -> 2.4795 | E15: =INDIRECT("'data'!C" & C15)/INDIRECT("'data'!B" & C15)/2*24*60 -> 240 | F15: 1080 | G15: =IFERROR(getCoinPrice($O15), $F15) -> 1127.808 | H15: =H14*D15 -> 520.2602 | I15: =G14*D15 -> 957.087 | J15: =INDIRECT("'data'!E" & C15) -> 44.539311 | K15: =INDIRECT("'data'!W" & C15) -> 0.95017198 | L15: =3*J17+3*J18+2*J19+2*J20+J21 -> 131.9419 | O15: 0x0f8f4dcf1b6eb9f5c0e8fbb9cd6879aa3983c8bc
A16: OIL | B16: =data!A454 -> OIL_10 | C16: =MATCH(B16, data!A:A, 0) -> 454 | D16: =INDIRECT("'data'!G" & C16)/INDIRECT("'data'!B" & C16) -> 2.4795 | E16: =INDIRECT("'data'!C" & C16)/INDIRECT("'data'!B" & C16)/2*24*60 -> 300 | F16: 2600 | G16: =IFERROR(getCoinPrice($O16), $F16) -> 2817.9143 | H16: =H15*D16 -> 1289.9852 | I16: =G15*D16 -> 2796.3999 | J16: =INDIRECT("'data'!E" & C16) -> -9.786705 | K16: =INDIRECT("'data'!W" & C16) -> -0.18605903 | O16: 0x6f363e6760876a4c66730fbbefccdd3014b6220c
A17: HEAT | B17: HEAT_29 | C17: =MATCH(B17, data!A:A, 0) -> 220 | D17: =INDIRECT("'data'!G" & C17)/INDIRECT("'data'!B" & C17) -> 5.89494 | E17: =INDIRECT("'data'!C" & C17)/INDIRECT("'data'!B" & C17)/2*24*60 -> 9.8 | F17: 70 | G17: =IFERROR(getCoinPrice($O17), $F17) -> 60.449433 | H17: =H4*D17 -> 0 | I17: =G4*D17 -> 57.180918 | J17: =INDIRECT("'data'!E" & C17) -> 10.758849 | K17: =INDIRECT("'data'!W" & C17) | L17: all | M17: gain / 12h | O17: 0x6ccd01c951e57d82be8dccb90c01a58bfb4d83cd
A18: LAVA | B18: LAVA_19 | C18: =MATCH(B18, data!A:A, 0) -> 262 | D18: =INDIRECT("'data'!G" & C18)/INDIRECT("'data'!B" & C18) -> 3.3218333 | E18: =INDIRECT("'data'!C" & C18)/INDIRECT("'data'!B" & C18)/2*24*60 -> 40 | F18: 240 | G18: =IFERROR(getCoinPrice($O18), $F18) -> 240 | H18: =H17*D18 -> 0 | I18: =G17*D18 -> 200.80294 | J18: =INDIRECT("'data'!E" & C18) -> 49.79559 | K18: =INDIRECT("'data'!W" & C18) -> 4.2289248 | L18: =L10+#REF!+L13+L15 -> #REF! | M18: =L18*12 -> #REF! | O18: 0x54ae64826ca9d440ede8c33e6cf4cfa1a3aa5801
A19: GLASS | B19: GLASS_5 | C19: =MATCH(B19, data!A:A, 0) -> 332 | D19: =INDIRECT("'data'!G" & C19)/INDIRECT("'data'!B" & C19) -> 164.47033 | E19: =INDIRECT("'data'!C" & C19)/INDIRECT("'data'!B" & C19)/2*24*60 -> 315 | F19: 470 | G19: =IFERROR(getCoinPrice($O19), $F19) -> 437.55081 | H19: =H18*D19 -> 0 | I19: =G17*D19 -> 9942.1383 | J19: =INDIRECT("'data'!E" & C19) -> -15.826075 | K19: =INDIRECT("'data'!W" & C19) -> -2.9281724 | O19: 0x7aa1cc00ca62982ab10d12fd4f6b6687f33011ad
A20: SULFUR | B20: SULFUR_2 | C20: =MATCH(B20, data!A:A, 0) -> 468 | D20: =INDIRECT("'data'!G" & C20)/INDIRECT("'data'!B" & C20) -> 7.5145 | E20: =INDIRECT("'data'!C" & C20)/INDIRECT("'data'!B" & C20)/2*24*60 -> 2520 | F20: 2421 | G20: =IFERROR(getCoinPrice($O20), $F20) -> 2421 | H20: =H19*D20 -> 0 | I20: =G19*D20 -> 3287.9756 | J20: =INDIRECT("'data'!E" & C20) -> -4.0524167 | K20: =INDIRECT("'data'!W" & C20) -> -0.48629 | M20: next step | O20: 0x346e30b7ca273fb001eec84fabf2b693617df710
A21: FIBERGLASS | B21: FIBERGLASS_2 | C21: =MATCH(B21, data!A:A, 0) -> 490 | D21: =INDIRECT("'data'!G" & C21)/INDIRECT("'data'!B" & C21) -> 9.88 | E21: =INDIRECT("'data'!C" & C21)/INDIRECT("'data'!B" & C21)/2*24*60 -> 3960 | F21: 8430 | G21: =IFERROR(getCoinPrice($O21), $F21) -> 8430 | H21: =H20*D21 -> 0 | I21: =G20*D21 -> 23919.48 | J21: =INDIRECT("'data'!E" & C21) -> -9.9644392 | K21: =INDIRECT("'data'!W" & C21) -> -1.2895157 | M21: 8 | O21: 0x0ffb7bd0bc009a01f9f9e95a0f563bad2189f151
A22: CERAMICS | B22: CERAMICS_10 | C22: =MATCH(B22, data!A:A, 0) -> 274 | D22: =INDIRECT("'data'!G" & C22)/INDIRECT("'data'!B" & C22) -> 263.40175 | E22: =INDIRECT("'data'!C" & C22)/INDIRECT("'data'!B" & C22)/2*24*60 -> 108.75 | F22: 80 | G22: =IFERROR(getCoinPrice($O22), $F22) -> 80 | H22: =H21*D22 -> 0 | I22: =G21*D22 -> 2220476.8 | J22: =INDIRECT("'data'!E" & C22) -> -1.253276 | K22: =INDIRECT("'data'!W" & C22) -> -0.14992824 | O22: 0xfa3a564b27deb29781f80032df662a4406eebef6
A23: STONE | B23: STONE_6 | C23: =MATCH(B23, data!A:A, 0) -> 370 | D23: =INDIRECT("'data'!G" & C23)/INDIRECT("'data'!B" & C23) -> 9.044 | E23: =INDIRECT("'data'!C" & C23)/INDIRECT("'data'!B" & C23)/2*24*60 -> 525 | F23: 320 | G23: =IFERROR(getCoinPrice($O23), $F23) -> 307.62219 | H23: =H22*D23 -> 0 | I23: =G22*D23 -> 723.52 | J23: =INDIRECT("'data'!E" & C23) -> 3.9474333 | K23: =INDIRECT("'data'!W" & C23) -> 0.49981248 | O23: 0xda4145a4975b1219e85a233673187309c4840044
A24: STEAM | B24: STEAM_1 | C24: =MATCH(B24, data!A:A, 0) -> 381 | D24: =INDIRECT("'data'!G" & C24)/INDIRECT("'data'!B" & C24) -> 1.9 | E24: =INDIRECT("'data'!C" & C24)/INDIRECT("'data'!B" & C24)/2*24*60 -> 960 | F24: 1250 | G24: =IFERROR(getCoinPrice($O24), $F24) -> 1250 | H24: =H23*D24 -> 0 | I24: =G23*D24 -> 584.48215 | J24: =INDIRECT("'data'!E" & C24) -> -5.528125 | K24: =INDIRECT("'data'!W" & C24) -> -0.8845 | O24: 0x7bf03c63adfded079adbd9f807ccce0fd28b8fd8
A25: CEMENT | B25: CEMENT_6 | C25: =MATCH(B25, data!A:A, 0) -> 434 | D25: =INDIRECT("'data'!G" & C25)/INDIRECT("'data'!B" & C25) -> 9.044 | E25: =INDIRECT("'data'!C" & C25)/INDIRECT("'data'!B" & C25)/2*24*60 -> 900 | F25: 1800 | G25: =IFERROR(getCoinPrice($O25), $F25) -> 1745.7678 | H25: =H24*D25 -> 0 | I25: =G24*D25 -> 11305 | J25: =INDIRECT("'data'!E" & C25) -> 9.5196096 | K25: =INDIRECT("'data'!W" & C25) -> 0.80674657 | O25: 0x491a412400840651c243acfc1ed9947ffe8a4e8f
A26: ACID | B26: ACID_4 | C26: =MATCH(B26, data!A:A, 0) -> 459 | D26: =INDIRECT("'data'!G" & C26)/INDIRECT("'data'!B" & C26) -> 1.8335 | E26: =INDIRECT("'data'!C" & C26)/INDIRECT("'data'!B" & C26)/2*24*60 -> 1500 | F26: 2250 | G26: =IFERROR(getCoinPrice($O26), $F26) -> 2250 | H26: =H25*D26 -> 0 | I26: =G25*D26 -> 3200.8653 | J26: =INDIRECT("'data'!E" & C26) -> -4.6943476 | K26: =INDIRECT("'data'!W" & C26) -> -0.3938211 | O26: 0xefc128c4cb990a5ecc88ff71e9efcc0eaef434d2
A27: PLASTICS | B27: PLASTICS_4 | C27: =MATCH(B27, data!A:A, 0) -> 481 | D27: =INDIRECT("'data'!G" & C27)/INDIRECT("'data'!B" & C27) -> 2.89 | E27: =INDIRECT("'data'!C" & C27)/INDIRECT("'data'!B" & C27)/2*24*60 -> 1920 | F27: 9000 | G27: =IFERROR(getCoinPrice($O27), $F27) -> 9000 | H27: =H26*D27 -> 0 | I27: =G26*D27 -> 6502.5 | J27: =INDIRECT("'data'!E" & C27) -> -12.363875 | K27: =INDIRECT("'data'!W" & C27) -> -0.90952643 | O27: 0x0ab775634107063a7c16c6c8e0fd6bda1f219ae6
A28: ENERGY | B28: ENERGY_5 | C28: =MATCH(B28, data!A:A, 0) -> 504 | D28: =INDIRECT("'data'!G" & C28)/INDIRECT("'data'!B" & C28) -> 1.9 | E28: =INDIRECT("'data'!C" & C28)/INDIRECT("'data'!B" & C28)/2*24*60 -> 1440 | F28: 9350 | G28: =IFERROR(getCoinPrice($O28), $F28) -> 9246.0247 | H28: =H27*D28 -> 0 | I28: =G27*D28 -> 17100 | J28: =INDIRECT("'data'!E" & C28) -> -10.988396 | K28: =INDIRECT("'data'!W" & C28) -> -0.47949363 | O28: 0xb0a3c31aae83526fd6ee75aac552822d676f46b2
A29: HYDROGEN | B29: HYDROGEN_5 | C29: =MATCH(B29, data!A:A, 0) -> 515 | D29: =INDIRECT("'data'!G" & C29)/INDIRECT("'data'!B" & C29) -> 6 | E29: =INDIRECT("'data'!C" & C29)/INDIRECT("'data'!B" & C29)/2*24*60 -> 720 | F29: 23000 | G29: =IFERROR(getCoinPrice($O29), $F29) -> 23546.634 | H29: =H28*D29 -> 0 | I29: =G28*D29 -> 55476.148 | J29: =INDIRECT("'data'!E" & C29) -> 14.524141 | K29: =INDIRECT("'data'!W" & C29) -> 0.25332804 | O29: 0xbb155716cd99d7ef8fd3fb45c91d39958c95b088
A30: DYNAMITE | B30: DYNAMITE_5 | C30: =MATCH(B30, data!A:A, 0) -> 521 | D30: =INDIRECT("'data'!G" & C30)/INDIRECT("'data'!B" & C30) -> 2.61 | E30: =INDIRECT("'data'!C" & C30)/INDIRECT("'data'!B" & C30)/2*24*60 -> 720 | F30: 39000 | G30: =IFERROR(getCoinPrice($O30), $F30) -> 39499.847 | H30: =H29*D30 -> 0 | I30: =G29*D30 -> 61456.716 | J30: =INDIRECT("'data'!E" & C30) -> 136.0876 | K30: =INDIRECT("'data'!W" & C30) -> 1.6330512 | O30: 0x85172e7ff5040366fa5a3caf7b1bd969bb06b570
F257: {=INDIRECT("renta!G$"& MATCH(A264,renta!$A:$A,0)-(H264*renta!$G$7)/C264-(L264*renta!$G$17)/C264)} -> #N/A

Sheet data
A1: ID | B1: OUTPUT | C1: DURATION | D1: gain coin/item | E1: coin/h | F1: INPUT 1 SYMBOL | G1: input1 | H1: INPUT 1 AMOUNT | I1: INPUT 2 SYMBOL | J1: input 2 | K1: INPUT 2 AMOUNT | L1: YIELD | M1: BATTERY COST | N1: XP PER OUTPUT | O1: COST SYMBOL | P1: COST AMOUNT | R1: cost update | S1: sum | U1: amélior coin/h/kcoin | V1: k power | W1: coin/kpower | X1: amélio coin/kpower | Y1: OUTPUT CHANGE | Z1: DURATION CHANGE | AA1: PRODUCTION CHANGE | AB1: INPUT 1 CONSUMPTION PER DAY | AC1: INPUT 1 PRODUCTION PER DAY AT SAME VALUE | AD1: INPUT 2 CONSUMPTION PER DAY | AE1: INPUT 2 PRODUCTION PER DAY AT SAME VALUE | AF1: OUTPUT PER BATTERY | AG1: XP PER DAY | AH1: XP PER BATTERY | AI1: bonus
A2: MUD_1 | B2: 1 | C2: 0.00011574074 | D2: {=IFERROR(INDIRECT("'renta'!G$"&MATCH(T2,renta!$A:$A,0))*0.975-(G2*INDIRECT("'renta'!G$"&MATCH(F2,renta!$A:$A,0)))/B2-IFERROR((J2*INDIRECT("'renta'!G$"&MATCH(I2,renta!$A:$A,0)))/B2,0),)} -> -0.00042824969 | E2: =IFERROR( D2/C2/24*B2*2*(1+AI2),0) -> -0.30833978 | F2: EARTH | G2: =H2*0.95 -> 2.85 | H2: 3,00 | L2: 100.00% | M2: 0 | N2: 1 | O2: EARTH | P2: 1 | R2: {=INDIRECT("'renta'!G$"&MATCH(O2,renta!$A:$A,0))*P2} -> 0.0041 | S2: =SUM(R$2:R2) -> 0.0041 | T2: =IFERROR(LEFT(A2, FIND("_", A2) - 1),"") -> MUD | U2: =(E2-E1)/R2*1000 -> #VALUE! | W2: =IFERROR(D2/V2*B2,) | Y2: 0 | Z2: 0 | AA2: 0 | AB2: 25920 | AC2: 28,800.00 | AF2: 1.00 | AG2: 8,640.00
A3: MUD_2 | B3: 2 | C3: 0.00011574074 | D3: {=IFERROR(INDIRECT("'renta'!G$"&MATCH(T3,renta!$A:$A,0))*0.975-(G3*INDIRECT("'renta'!G$"&MATCH(F3,renta!$A:$A,0)))/B3-IFERROR((J3*INDIRECT("'renta'!G$"&MATCH(I3,renta!$A:$A,0)))/B3,0),)} -> -0.00042824969 | E3: =IFERROR( D3/C3/24*B3*2*(1+AI3),0) -> -0.61667956 | F3: EARTH | G3: =H3*0.95 -> 5.7 | H3: 6,00 | L3: 100.00% | M3: 0 | N3: 1 | O3: MUD | P3: 3 | R3: {=INDIRECT("'renta'!G$"&MATCH(O3,renta!$A:$A,0))*P3} -> 0.034636155 | S3: =SUM(R$2:R3) -> 0.038736155 | T3: =IFERROR(LEFT(A3, FIND("_", A3) - 1),"") -> MUD | U3: =(E3-E2)/R3*1000 -> -8902.252 | W3: =IFERROR(D3/V3*B3,) | Y3: 1 | Z3: 0 | AA3: 1 | AB3: 51,840.00 | AC3: 57,600.00 | AF3: 2.00 | AG3: 17,280.00
A4: MUD_3 | B4: 4 | C4: 0.00016203704 | D4: {=IFERROR(INDIRECT("'renta'!G$"&MATCH(T4,renta!$A:$A,0))*0.975-(G4*INDIRECT("'renta'!G$"&MATCH(F4,renta!$A:$A,0)))/B4-IFERROR((J4*INDIRECT("'renta'!G$"&MATCH(I4,renta!$A:$A,0)))/B4,0),)} -> -0.00042824969 | E4: =IFERROR( D4/C4/24*B4*2*(1+AI4),0) -> -0.8809708 | F4: EARTH | G4: =H4*0.95 -> 11.4 | H4: 12,00 | L4: 100.00% | M4: 0 | N4: 1 | O4: MUD | P4: 6 | R4: {=INDIRECT("'renta'!G$"&MATCH(O4,renta!$A:$A,0))*P4} -> 0.06927231 | S4: =SUM(R$2:R4) -> 0.10800846 | T4: =IFERROR(LEFT(A4, FIND("_", A4) - 1),"") -> MUD | U4: =(E4-E3)/R4*1000 -> -3815.2509 | W4: =IFERROR(D4/V4*B4,) | Y4: 2 | Z4: 4.6296296e-05 | AA4: 47.22% | AB4: 76,320.00 | AC4: 86,400.00 | AF4: 4.00 | AG4: 25,440.00
A5: MUD_4 | B5: 14 | C5: 0.00042824074 | D5: {=IFERROR(INDIRECT("'renta'!G$"&MATCH(T5,renta!$A:$A,0))*0.975-(G5*INDIRECT("'renta'!G$"&MATCH(F5,renta!$A:$A,0)))/B5-IFERROR((J5*INDIRECT("'renta'!G$"&MATCH(I5,renta!$A:$A,0)))/B5,0),)} -> -0.00042824969 | E5: =IFERROR( D5/C5/24*B5*2*(1+AI5),0) -> -1.1666911 | F5: EARTH | G5: =H5*0.95 -> 39.9 | H5: 42,00 | L5: 100.00% | M5: 2 | N5: 1 | O5: CLAY | P5: 2 | R5: {=INDIRECT("'renta'!G$"&MATCH(O5,renta!$A:$A,0))*P5} -> 0.24 | S5: =SUM(R$2:R5) -> 0.34800846 | T5: =IFERROR(LEFT(A5, FIND("_", A5) - 1),"") -> MUD | U5: =(E5-E4)/R5*1000 -> -1190.5011 | W5: =IFERROR(D5/V5*B5,) | Y5: 10 | Z5: 0.0002662037 | AA5: 30.19% | AB5: 99,360.00 | AC5: 129,600.00 | AF5: 7.00 | AG5: 33,120.00 | AH5: 7
A6: MUD_5 | B6: 28 | C6: 0.00069444444 | D6: {=IFERROR(INDIRECT("'renta'!G$"&MATCH(T6,renta!$A:$A,0))*0.975-(G6*INDIRECT("'renta'!G$"&MATCH(F6,renta!$A:$A,0)))/B6-IFERROR((J6*INDIRECT("'renta'!G$"&MATCH(I6,renta!$A:$A,0)))/B6,0),)} -> -0.00042824969 | E6: =IFERROR( D6/C6/24*B6*2*(1+AI6),0) -> -1.438919 | F6: EARTH | G6: =H6*0.95 -> 79.8 | H6: 84,00 | L6: 100.00% | M6: 4 | N6: 1 | O6: SAND | P6: 2 | R6: {=INDIRECT("'renta'!G$"&MATCH(O6,renta!$A:$A,0))*P6} -> 0.62353859 | S6: =SUM(R$2:R6) -> 0.97154705 | T6: =IFERROR(LEFT(A6, FIND("_", A6) - 1),"") -> MUD | U6: =(E6-E5)/R6*1000 -> -436.58551 | W6: =IFERROR(D6/V6*B6,) | Y6: 14 | Z6: 0.0002662037 | AA6: 21.74% | AB6: 120,960.00 | AC6: 216,000.00 | AF6: 7.00 | AG6: 40,320.00 | AH6: 7
A7: MUD_6 | B7: 65 | C7: 0.0013888889 | D7: {=IFERROR(INDIRECT("'renta'!G$"&MATCH(T7,renta!$A:$A,0))*0.975-(G7*INDIRECT("'renta'!G$"&MATCH(F7,renta!$A:$A,0)))/B7-IFERROR((J7*INDIRECT("'renta'!G$"&MATCH(I7,renta!$A:$A,0)))/B7,0),)} -> -0.00042824969 | E7: =IFERROR( D7/C7/24*B7*2*(1+AI7),0) -> -1.6701738 | F7: EARTH | G7: =H7*0.95 -> 185.25 | H7: 195,00 | L7: 100.00% | M7: 10 | N7: 1 | O7: SAND | P7: 4 | R7: {=INDIRECT("'renta'!G$"&MATCH(O7,renta!$A:$A,0))*P7} -> 1.2470772 | S7: =SUM(R$2:R7) -> 2.2186242 | T7: =IFERROR(LEFT(A7, FIND("_", A7) - 1),"") -> MUD | U7: =(E7-E6)/R7*1000 -> -185.43747 | W7: =IFERROR(D7/V7*B7,) | Y7: 37 | Z7: 0.00069444444 | AA7: 16.07% | AB7: 140,400.00 | AC7: 264,000.00 | AF7: 6.50 | AG7: 46,800.00 | AH7: 7
A8: MUD_7 | B8: 185 | C8: 0.0034722222 | D8: {=IFERROR(INDIRECT("'renta'!G$"&MATCH(T8,renta!$A:$A,0))*0.975-(G8*INDIRECT("'renta'!G$"&MATCH(F8,renta!$A:$A,0)))/B8-IFERROR((J8*INDIRECT("'renta'!G$"&MATCH(I8,renta!$A:$A,0)))/B8,0),)} -> -0.00042824969 | E8: =IFERROR( D8/C8/24*B8*2*(1+AI8),0) -> -1.9014286 | F8: EARTH | G8: =H8*0.95 -> 527.25 | H8: 555,00 | L8: 100.00% | M8: 27 | N8: 1 | O8: SAND | P8: 6 | R8: {=INDIRECT("'renta'!G$"&MATCH(O8,renta!$A:$A,0))*P8} -> 1.8706158 | S8: =SUM(R$2:R8) -> 4.08924 | T8: =IFERROR(LEFT(A8, FIND("_", A8) - 1),"") -> MUD | U8: =(E8-E7)/R8*1000 -> -123.62498 | W8: =IFERROR(D8/V8*B8,) | Y8: 120 | Z8: 0.0020833333 | AA8: 13.85% | AB8: 159,840.00 | AC8: 264,000.00 | AF8: 6.85 | AG8: 53,280.00 | AH8: 7
A9: MUD_8 | B9: 412 | C9: 0.0069444444 | D9: {=IFERROR(INDIRECT("'renta'!G$"&MATCH(T9,renta!$A:$A,0))*0.975-(G9*INDIRECT("'renta'!G$"&MATCH(F9,renta!$A:$A,0)))/B9-IFERROR((J9*INDIRECT("'renta'!G$"&MATCH(I9,renta!$A:$A,0)))/B9,0),)} -> -0.00042824969 | E9: =IFERROR( D9/C9/24*B9*2*(1+AI9),0) -> -2.1172665 | F9: EARTH | G9: =H9*0.95 -> 1174.2 | H9: 1236,00 | L9: 100.00% | M9: 59 | N9: 1 | O9: SAND | P9: 20 | R9: {=INDIRECT("'renta'!G$"&MATCH(O9,renta!$A:$A,0))*P9} -> 6.2353859 | S9: =SUM(R$2:R9) -> 10.324626 | T9: =IFERROR(LEFT(A9, FIND("_", A9) - 1),"") -> MUD | U9: =(E9-E8)/R9*1000 -> -34.614994 | W9: =IFERROR(D9/V9*B9,) | Y9: 227 | Z9: 0.0034722222 | AA9: 11.26% | AB9: 177,840.00 | AC9: 360,000.00 | AF9: 6.98 | AG9: 59,280.00 | AH9: 7
A10: MUD_9 | B10: 903 | C10: 0.013888889 | D10: {=IFERROR(INDIRECT("'renta'!G$"&MATCH(T10,renta!$A:$A,0))*0.975-(G10*INDIRECT("'renta'!G$"&MATCH(F10,renta!$A:$A,0)))/B10-IFERROR((J10*INDIRECT("'renta'!G$"&MATCH(I10,renta!$A:$A,0)))/B10,0),)} -> -0.00042824969 | E10: =IFERROR( D10/C10/24*B10*2*(1+AI10),0) -> -2.3202568 | F10: EARTH | G10: =H10*0.95 -> 2573.55 | H10: 2709,00 | L10: 100.00% | M10: 129 | N10: 1 | O10: SAND | P10: 35 | R10: {=INDIRECT("'renta'!G$"&MATCH(O10,renta!$A:$A,0))*P10} -> 10.911925 | S10: =SUM(R$2:R10) -> 21.236551 | T10: =IFERROR(LEFT(A10, FIND("_", A10) - 1),"") -> MUD | U10: =(E10-E9)/R10*1000 -> -18.602616 | W10: =IFERROR(D10/V10*B10,) | Y10: 491 | Z10: 0.0069328704 | AA10: 9.72% | AB10: 195,120.00 | AC10: 360,000.00 | AF10: 7.00 | AG10: 65,040.00 | AH10: 7
A11: MUD_10 | B11: 1470 | C11: 0.020833333 | D11: {=IFERROR(INDIRECT("'renta'!G$"&MATCH(T11,renta!$A:$A,0))*0.975-(G11*INDIRECT("'renta'!G$"&MATCH(F11,renta!$A:$A,0)))/B11-IFERROR((J11*INDIRECT("'renta'!G$"&MATCH(I11,renta!$A:$A,0)))/B11,0),)} -> -0.00042824969 | E11: =IFERROR( D11/C11/24*B11*2*(1+AI11),0) -> -2.5181082 | F11: EARTH | G11: =H11*0.95 -> 4189.5 | H11: 4410,00 | L11: 100.00% | M11: 210 | N11: 1 | O11: SAND | P11: 50 | R11: {=INDIRECT("'renta'!G$"&MATCH(O11,renta!$A:$A,0))*P11} -> 15.588465 | S11: =SUM(R$2:R11) -> 36.825016 | T11: =IFERROR(LEFT(A11, FIND("_", A11) - 1),"") -> MUD | U11: =(E11-E10)/R11*1000 -> -12.692164 | W11: =IFERROR(D11/V11*B11,) | Y11: 567 | Z11: 0.0069444444 | AA11: 8.49% | AB11: 211,680.00 | AC11: 360,000.00 | AF11: 7.00 | AG11: 70,560.00 | AH11: 7
A12: MUD_11 | B12: 2107 | C12: 0.027777778 | D12: {=IFERROR(INDIRECT("'renta'!G$"&MATCH(T12,renta!$A:$A,0))*0.975-(G12*INDIRECT("'renta'!G$"&MATCH(F12,renta!$A:$A,0)))/B12-IFERROR((J12*INDIRECT("'renta'!G$"&MATCH(I12,renta!$A:$A,0)))/B12,0),)} -> -0.00042824969 | E12: =IFERROR( D12/C12/24*B12*2*(1+AI12),0) -> -2.7069663 | F12: EARTH | G12: =H12*0.95 -> 6004.95 | H12: 6321,00 | L12: 100.00% | M12: 301 | N12: 1 | O12: COPPER | P12: 2 | R12: {=INDIRECT("'renta'!G$"&MATCH(O12,renta!$A:$A,0))*P12} -> 16.66 | S12: =SUM(R$2:R12) -> 53.485016 | T12: =IFERROR(LEFT(A12, FIND("_", A12) - 1),"") -> MUD | U12: =(E12-E11)/R12*1000 -> -11.336021 | W12: =IFERROR(D12/V12*B12,) | Y12: 637 | Z12: 0.0069444444 | AA12: 7.48% | AB12: 227,520.00 | AC12: 360,000.00 | AF12: 7.00 | AG12: 75,840.00 | AH12: 7
A13: MUD_12 | B13: 2527 | C13: 0.031238426 | D13: {=IFERROR(INDIRECT("'renta'!G$"&MATCH(T13,renta!$A:$A,0))*0.975-(G13*INDIRECT("'renta'!G$"&MATCH(F13,renta!$A:$A,0)))/B13-IFERROR((J13*INDIRECT("'renta'!G$"&MATCH(I13,renta!$A:$A,0)))/B13,0),)} -> -0.00042824969 | E13: =IFERROR( D13/C13/24*B13*2*(1+AI13),0) -> -2.8869012 | F13: EARTH | G13: =H13*0.95 -> 7201.95 | H13: 7581,00 | L13: 100.00% | M13: 361 | N13: 1 | O13: COPPER | P13: 3 | R13: {=INDIRECT("'renta'!G$"&MATCH(O13,renta!$A:$A,0))*P13} -> 24.99 | S13: =SUM(R$2:R13) -> 78.475016 | T13: =IFERROR(LEFT(A13, FIND("_", A13) - 1),"") -> MUD | U13: =(E13-E12)/R13*1000 -> -7.2002739 | W13: =IFERROR(D13/V13*B13,) | Y13: 420 | Z13: 0.0034606481 | AA13: 6.65% | AB13: 242,640.00 | AC13: 360,000.00 | AF13: 7.00 | AG13: 80,880.00 | AH13: 7
A14: MUD_13 | B14: 2975 | C14: 0.034722222 | D14: {=IFERROR(INDIRECT("'renta'!G$"&MATCH(T14,renta!$A:$A,0))*0.975-(G14*INDIRECT("'renta'!G$"&MATCH(F14,renta!$A:$A,0)))/B14-IFERROR((J14*INDIRECT("'renta'!G$"&MATCH(I14,renta!$A:$A,0)))/B14,0),)} -> -0.00042824969 | E14: =IFERROR( D14/C14/24*B14*2*(1+AI14),0) -> -3.0577028 | F14: EARTH | G14: =H14*0.95 -> 8478.75 | H14: 8925,00 | L14: 100.00% | M14: 425 | N14: 1 | O14: COPPER | P14: 5 | R14: {=INDIRECT("'renta'!G$"&MATCH(O14,renta!$A:$A,0))*P14} -> 41.65 | S14: =SUM(R$2:R14) -> 120.12502 | T14: =IFERROR(LEFT(A14, FIND("_", A14) - 1),"") -> MUD | U14: =(E14-E13)/R14*1000 -> -4.1008801 | W14: =IFERROR(D14/V14*B14,) | Y14: 448 | Z14: 0.0034837963 | AA14: 5.93% | AB14: 257,040.00 | AC14: 360,000.00 | AF14: 7.00 | AG14: 85,680.00 | AH14: 7
A15: MUD_14 | B15: 3384 | C15: 0.0375 | D15: {=IFERROR(INDIRECT("'renta'!G$"&MATCH(T15,renta!$A:$A,0))*0.975-(G15*INDIRECT("'renta'!G$"&MATCH(F15,renta!$A:$A,0)))/B15-IFERROR((J15*INDIRECT("'renta'!G$"&MATCH(I15,renta!$A:$A,0)))/B15,0),)} -> -0.00042824969 | E15: =IFERROR( D15/C15/24*B15*2*(1+AI15),0) -> -3.2204377 | F15: EARTH | G15: =H15*0.95 -> 9644.4 | H15: 10152,00 | L15: 100.00% | M15: 484 | N15: 1 | O15: COPPER | P15: 8 | R15: {=INDIRECT("'renta'!G$"&MATCH(O15,renta!$A:$A,0))*P15} -> 66.64 | S15: =SUM(R$2:R15) -> 186.76502 | T15: =IFERROR(LEFT(A15, FIND("_", A15) - 1),"") -> MUD | U15: =(E15-E14)/R15*1000 -> -2.4420001 | W15: =IFERROR(D15/V15*B15,) | Y15: 409 | Z15: 0.0027777778 | AA15: 5.32% | AB15: 270,720.00 | AC15: 360,000.00 | AF15: 6.99 | AG15: 90,240.00 | AH15: 7
A16: MUD_15 | B16: 3743 | C16: 0.039583333 | D16: {=IFERROR(INDIRECT("'renta'!G$"&MATCH(T16,renta!$A:$A,0))*0.975-(G16*INDIRECT("'renta'!G$"&MATCH(F16,renta!$A:$A,0)))/B16-IFERROR((J16*INDIRECT("'renta'!G$"&MATCH(I16,renta!$A:$A,0)))/B16,0),)} -> -0.00042824969 | E16: =IFERROR( D16/C16/24*B16*2*(1+AI16),0) -> -3.3746076 | F16: EARTH | G16: =H16*0.95 -> 10667.55 | H16: 11229,00 | L16: 100.00% | M16: 535 | N16: 1 | O16: COPPER | P16: 12 | R16: {=INDIRECT("'renta'!G$"&MATCH(O16,renta!$A:$A,0))*P16} -> 99.96 | S16: =SUM(R$2:R16) -> 286.72502 | T16: =IFERROR(LEFT(A16, FIND("_", A16) - 1),"") -> MUD | U16: =(E16-E15)/R16*1000 -> -1.5423158 | W16: =IFERROR(D16/V16*B16,) | Y16: 359 | Z16: 0.0020833333 | AA16: 4.79% | AB16: 283,680.00 | AC16: 360,000.00 | AF16: 7.00 | AG16: 94,560.00 | AH16: 7
A17: MUD_16 | B17: 4110 | C17: 0.041666667 | D17: {=IFERROR(INDIRECT("'renta'!G$"&MATCH(T17,renta!$A:$A,0))*0.975-(G17*INDIRECT("'renta'!G$"&MATCH(F17,renta!$A:$A,0)))/B17-IFERROR((J17*INDIRECT("'renta'!G$"&MATCH(I17,renta!$A:$A,0)))/B17,0),)} -> -0.00042824969 | E17: =IFERROR( D17/C17/24*B17*2*(1+AI17),0) -> -3.5202125 | F17: EARTH | G17: =H17*0.95 -> 11713.5 | H17: 12330,00 | L17: 100.00% | M17: 588 | N17: 1 | O17: COPPER | P17: 16 | R17: {=INDIRECT("'renta'!G$"&MATCH(O17,renta!$A:$A,0))*P17} -> 133.28 | S17: =SUM(R$2:R17) -> 420.00502 | T17: =IFERROR(LEFT(A17, FIND("_", A17) - 1),"") -> MUD | U17: =(E17-E16)/R17*1000 -> -1.0924737 | W17: =IFERROR(D17/V17*B17,) | Y17: 367 | Z17: 0.0020833333 | AA17: 4.31% | AB17: 295,920.00 | AC17: 360,000.00 | AF17: 6.99 | AG17: 98,640.00 | AH17: 7
A18: MUD_17 | B18: 4412 | C18: 0.043055556 | D18: {=IFERROR(INDIRECT("'renta'!G$"&MATCH(T18,renta!$A:$A,0))*0.975-(G18*INDIRECT("'renta'!G$"&MATCH(F18,renta!$A:$A,0)))/B18-IFERROR((J18*INDIRECT("'renta'!G$"&MATCH(I18,renta!$A:$A,0)))/B18,0),)} -> -0.00042824969 | E18: =IFERROR( D18/C18/24*B18*2*(1+AI18),0) -> -3.6569761 | F18: EARTH | G18: =H18*0.95 -> 12574.2 | H18: 13236,00 | L18: 100.00% | M18: 631 | N18: 1 | O18: COPPER | P18: 21 | R18: {=INDIRECT("'renta'!G$"&MATCH(O18,renta!$A:$A,0))*P18} -> 174.93 | S18: =SUM(R$2:R18) -> 594.93502 | T18: =IFERROR(LEFT(A18, FIND("_", A18) - 1),"") -> MUD | U18: =(E18-E17)/R18*1000 -> -0.78181908 | V18: 0.631 | W18: =IFERROR(D18/V18*B18,) -> -2.9943544 | Y18: 302 | Z18: 0.0013888889 | AA18: 3.89% | AB18: 307,440.00 | AC18: 360,000.00 | AF18: 6.99 | AG18: 102,480.00 | AH18: 7
A19: MUD_18 | B19: 4714 | C19: 0.044444444 | D19: {=IFERROR(INDIRECT("'renta'!G$"&MATCH(T19,renta!$A:$A,0))*0.975-(G19*INDIRECT("'renta'!G$"&MATCH(F19,renta!$A:$A,0)))/B19-IFERROR((J19*INDIRECT("'renta'!G$"&MATCH(I19,renta!$A:$A,0)))/B19,0),)} -> -0.00042824969 | E19: =IFERROR( D19/C19/24*B19*2*(1+AI19),0) -> -3.785192 | F19: EARTH | G19: =H19*0.95 -> 13434.9 | H19: 14142,00 | L19: 100.00% | M19: 674 | N19: 1 | O19: COPPER | P19: 26 | R19: {=INDIRECT("'renta'!G$"&MATCH(O19,renta!$A:$A,0))*P19} -> 216.58 | S19: =SUM(R$2:R19) -> 811.51502 | T19: =IFERROR(LEFT(A19, FIND("_", A19) - 1),"") -> MUD | U19: =(E19-E18)/R19*1000 -> -0.59200243 | W19: =IFERROR(D19/V19*B19,) | Y19: 302 | Z19: 0.0013888889 | AA19: 3.5% | AB19: 318,195.00 | AC19: 360,000.00 | AF19: 6.99 | AG19: 106,065.00 | AH19: 7
A20: MUD_19 | B20: 5016 | C20: 0.045833333 | D20: {=IFERROR(INDIRECT("'renta'!G$"&MATCH(T20,renta!$A:$A,0))*0.975-(G20*INDIRECT("'renta'!G$"&MATCH(F20,renta!$A:$A,0)))/B20-IFERROR((J20*INDIRECT("'renta'!G$"&MATCH(I20,renta!$A:$A,0)))/B20,0),)} -> -0.00042824969 | E20: =IFERROR( D20/C20/24*B20*2*(1+AI20),0) -> -3.9056372 | F20: EARTH | G20: =H20*0.95 -> 14295.6 | H20: 15048,00 | L20: 100.00% | M20: 717 | N20: 1 | O20: COPPER | P20: 32 | R20: {=INDIRECT("'renta'!G$"&MATCH(O20,renta!$A:$A,0))*P20} -> 266.56 | S20: =SUM(R$2:R20) -> 1078.075 | T20: =IFERROR(LEFT(A20, FIND("_", A20) - 1),"") -> MUD | U20: =(E20-E19)/R20*1000 -> -0.45185034 | W20: =IFERROR(D20/V20*B20,) | Y20: 302 | Z20: 0.0013888889 | AA20: 3.18% | AB20: 328,320.00 | AC20: 360,000.00 | AF20: 7.00 | AG20: 109,440.00 | AH20: 7
A21: MUD_20 | B21: 5315 | C21: 0.047222222 | D21: {=IFERROR(INDIRECT("'renta'!G$"&MATCH(T21,renta!$A:$A,0))*0.975-(G21*INDIRECT("'renta'!G$"&MATCH(F21,renta!$A:$A,0)))/B21-IFERROR((J21*INDIRECT("'renta'!G$"&MATCH(I21,renta!$A:$A,0)))/B21,0),)} -> -0.00042824969 | E21: =IFERROR( D21/C21/24*B21*2*(1+AI21),0) -> -4.0167302 | F21: EARTH | G21: =H21*0.95 -> 15147.75 | H21: 15945,00 | L21: 100.00% | M21: 760 | N21: 1 | O21: COPPER | P21: 39 | R21: {=INDIRECT("'renta'!G$"&MATCH(O21,renta!$A:$A,0))*P21} -> 324.87 | S21: =SUM(R$2:R21) -> 1402.945 | T21: =IFERROR(LEFT(A21, FIND("_", A21) - 1),"") -> MUD | U21: =(E21-E20)/R21*1000 -> -0.34196143 | W21: =IFERROR(D21/V21*B21,) | Y21: 299 | Z21: 0.0013888889 | AA21: 2.85% | AB21: 337,680.00 | AC21: 360,000.00 | AF21: 6.99 | AG21: 112,560.00 | AH21: 7
A22: MUD_21 | B22: 5611 | C22: 0.048611111 | D22: {=IFERROR(INDIRECT("'renta'!G$"&MATCH(T22,renta!$A:$A,0))*0.975-(G22*INDIRECT("'renta'!G$"&MATCH(F22,renta!$A:$A,0)))/B22-IFERROR((J22*INDIRECT("'renta'!G$"&MATCH(I22,renta!$A:$A,0)))/B22,0),)} -> -0.00042824969 | E22: =IFERROR( D22/C22/24*B22*2*(1+AI22),0) -> -4.1192726 | F22: EARTH | G22: =H22*0.95 -> 15991.35 | H22: 16833,00 | L22: 100.00% | M22: 802 | N22: 1 | O22: COPPER | P22: 47 | R22: {=INDIRECT("'renta'!G$"&MATCH(O22,renta!$A:$A,0))*P22} -> 391.51 | S22: =SUM(R$2:R22) -> 1794.455 | T22: =IFERROR(LEFT(A22, FIND("_", A22) - 1),"") -> MUD | U22: =(E22-E21)/R22*1000 -> -0.26191517 | W22: =IFERROR(D22/V22*B22,) | Y22: 296 | Z22: 0.0013888889 | AA22: 2.56% | AB22: 346,320.00 | AC22: 360,000.00 | AF22: 7.00 | AG22: 115,440.00 | AH22: 7
A23: MUD_22 | B23: 5910 | C23: 0.05 | D23: {=IFERROR(INDIRECT("'renta'!G$"&MATCH(T23,renta!$A:$A,0))*0.975-(G23*INDIRECT("'renta'!G$"&MATCH(F23,renta!$A:$A,0)))/B23-IFERROR((J23*INDIRECT("'renta'!G$"&MATCH(I23,renta!$A:$A,0)))/B23,0),)} -> -0.00042824969 | E23: =IFERROR( D23/C23/24*B23*2*(1+AI23),0) -> -4.2182595 | F23: EARTH | G23: =H23*0.95 -> 16843.5 | H23: 17730,00 | L23: 100.00% | M23: 845 | N23: 1 | O23: COPPER | P23: 55 | R23: {=INDIRECT("'renta'!G$"&MATCH(O23,renta!$A:$A,0))*P23} -> 458.15 | S23: =SUM(R$2:R23) -> 2252.605 | T23: =IFERROR(LEFT(A23, FIND("_", A23) - 1),"") -> MUD | U23: =(E23-E22)/R23*1000 -> -0.21605775 | W23: =IFERROR(D23/V23*B23,) | Y23: 299 | Z23: 0.0013888889 | AA23: 2.39% | AB23: 354,600.00 | AC23: 360,000.00 | AF23: 6.99 | AG23: 118,200.00 | AH23: 7
A24: MUD_23 | B24: 6210 | C24: 0.051388889 | D24: {=IFERROR(INDIRECT("'renta'!G$"&MATCH(T24,renta!$A:$A,0))*0.975-(G24*INDIRECT("'renta'!G$"&MATCH(F24,renta!$A:$A,0)))/B24-IFERROR((J24*INDIRECT("'renta'!G$"&MATCH(I24,renta!$A:$A,0)))/B24,0),)} -> -0.00042824969 | E24: =IFERROR( D24/C24/24*B24*2*(1+AI24),0) -> -4.3125902 | F24: EARTH | G24: =H24*0.95 -> 17698.5 | H24: 18630,00 | L24: 100.00% | M24: 888 | N24: 1 | O24: COPPER | P24: 64 | R24: {=INDIRECT("'renta'!G$"&MATCH(O24,renta!$A:$A,0))*P24} -> 533.12 | S24: =SUM(R$2:R24) -> 2785.725 | T24: =IFERROR(LEFT(A24, FIND("_", A24) - 1),"") -> MUD | U24: =(E24-E23)/R24*1000 -> -0.17694079 | W24: =IFERROR(D24/V24*B24,) | Y24: 300 | Z24: 0.0013888889 | AA24: 2.23% | AB24: 362,520.00 | AC24: 360,000.00 | AF24: 6.99 | AG24: 120,840.00 | AH24: 7
A25: MUD_24 | B25: 6511 | C25: 0.052777778 | D25: {=IFERROR(INDIRECT("'renta'!G$"&MATCH(T25,renta!$A:$A,0))*0.975-(G25*INDIRECT("'renta'!G$"&MATCH(F25,renta!$A:$A,0)))/B25-IFERROR((J25*INDIRECT("'renta'!G$"&MATCH(I25,renta!$A:$A,0)))/B25,0),)} -> -0.00042824969 | E25: =IFERROR( D25/C25/24*B25*2*(1+AI25),0) -> -4.4026322 | F25: EARTH | G25: =H25*0.95 -> 18556.35 | H25: 19533,00 | L25: 100.00% | M25: 931 | N25: 1 | O25: COPPER | P25: 75 | R25: {=INDIRECT("'renta'!G$"&MATCH(O25,renta!$A:$A,0))*P25} -> 624.75 | S25: =SUM(R$2:R25) -> 3410.475 | T25: =IFERROR(LEFT(A25, FIND("_", A25) - 1),"") -> MUD | U25: =(E25-E24)/R25*1000 -> -0.14412499 | W25: =IFERROR(D25/V25*B25,) | Y25: 301 | Z25: 0.0013888889 | AA25: 2.09% | AB25: 370,080.00 | AC25: 360,000.00 | AF25: 6.99 | AG25: 123,360.00 | AH25: 7
A26: MUD_25 | B26: 6812 | C26: 0.054166667 | D26: {=IFERROR(INDIRECT("'renta'!G$"&MATCH(T26,renta!$A:$A,0))*0.975-(G26*INDIRECT("'renta'!G$"&MATCH(F26,renta!$A:$A,0)))/B26-IFERROR((J26*INDIRECT("'renta'!G$"&MATCH(I26,renta!$A:$A,0)))/B26,0),)} -> -0.00042824969 | E26: =IFERROR( D26/C26/24*B26*2*(1+AI26),0) -> -4.4880568 | F26: EARTH | G26: =H26*0.95 -> 19414.2 | H26: 20436,00 | L26: 100.00% | M26: 974 | N26: 1 | O26: STEEL | P26: 17 | R26: {=INDIRECT("'renta'!G$"&MATCH(O26,renta!$A:$A,0))*P26} -> 629 | S26: =SUM(R$2:R26) -> 4039.475 | T26: =IFERROR(LEFT(A26, FIND("_", A26) - 1),"") -> MUD | U26: =(E26-E25)/R26*1000 -> -0.13581009 | W26: =IFERROR(D26/V26*B26,) | Y26: 301 | Z26: 0.0013888889 | AA26: 1.95% | AB26: 377,280.00 | AC26: 360,000.00 | AF26: 6.99 | AG26: 125,760.00 | AH26: 7
A27: MUD_26 | B27: 7116 | C27: 0.055555556 | D27: {=IFERROR(INDIRECT("'renta'!G$"&MATCH(T27,renta!$A:$A,0))*0.975-(G27*INDIRECT("'renta'!G$"&MATCH(F27,renta!$A:$A,0)))/B27-IFERROR((J27*INDIRECT("'renta'!G$"&MATCH(I27,renta!$A:$A,0)))/B27,0),)} -> -0.00042824969 | E27: =IFERROR( D27/C27/24*B27*2*(1+AI27),0) -> -4.5711372 | F27: EARTH | G27: =H27*0.95 -> 20280.6 | H27: 21348,00 | L27: 100.00% | M27: 1.017 | N27: 1 | O27: STEEL | P27: 20 | R27: {=INDIRECT("'renta'!G$"&MATCH(O27,renta!$A:$A,0))*P27} -> 740 | S27: =SUM(R$2:R27) -> 4779.475 | T27: =IFERROR(LEFT(A27, FIND("_", A27) - 1),"") -> MUD | U27: =(E27-E26)/R27*1000 -> -0.11227087 | W27: =IFERROR(D27/V27*B27,) | Y27: 304 | Z27: 0.0013888889 | AA27: 1.85% | AB27: 384,264.00 | AC27: 360,000.00 | AF27: 7.00 | AG27: 128,088.00 | AH27: 7
A28: MUD_27 | B28: 7422 | C28: 0.056944444 | D28: {=IFERROR(INDIRECT("'renta'!G$"&MATCH(T28,renta!$A:$A,0))*0.975-(G28*INDIRECT("'renta'!G$"&MATCH(F28,renta!$A:$A,0)))/B28-IFERROR((J28*INDIRECT("'renta'!G$"&MATCH(I28,renta!$A:$A,0)))/B28,0),)} -> -0.00042824969 | E28: =IFERROR( D28/C28/24*B28*2*(1+AI28),0) -> -4.6514184 | F28: EARTH | G28: =H28*0.95 -> 21152.7 | H28: 22266,00 | L28: 100.00% | M28: 1.061 | N28: 1 | O28: STEEL | P28: 23 | R28: {=INDIRECT("'renta'!G$"&MATCH(O28,renta!$A:$A,0))*P28} -> 851 | S28: =SUM(R$2:R28) -> 5630.475 | T28: =IFERROR(LEFT(A28, FIND("_", A28) - 1),"") -> MUD | U28: =(E28-E27)/R28*1000 -> -0.094337426 | W28: =IFERROR(D28/V28*B28,) | Y28: 306 | Z28: 0.0013888889 | AA28: 1.76% | AB28: 391,032.00 | AC28: 360,000.00 | AF28: 7.00 | AG28: 130,344.00 | AH28: 7
A29: MUD_28 | B29: 7730 | C29: 0.058321759 | D29: {=IFERROR(INDIRECT("'renta'!G$"&MATCH(T29,renta!$A:$A,0))*0.975-(G29*INDIRECT("'renta'!G$"&MATCH(F29,renta!$A:$A,0)))/B29-IFERROR((J29*INDIRECT("'renta'!G$"&MATCH(I29,renta!$A:$A,0)))/B29,0),)} -> -0.00042824969 | E29: =IFERROR( D29/C29/24*B29*2*(1+AI29),0) -> -4.7300387 | F29: EARTH | G29: =H29*0.95 -> 22030.5 | H29: 23190,00 | L29: 100.00% | M29: 1.105 | N29: 1 | O29: STEEL | P29: 26 | R29: {=INDIRECT("'renta'!G$"&MATCH(O29,renta!$A:$A,0))*P29} -> 962 | S29: =SUM(R$2:R29) -> 6592.475 | T29: =IFERROR(LEFT(A29, FIND("_", A29) - 1),"") -> MUD | U29: =(E29-E28)/R29*1000 -> -0.081725892 | W29: =IFERROR(D29/V29*B29,) | Y29: 308 | Z29: 0.0013888889 | AA29: 1.68% | AB29: 397,584.00 | AC29: 360,000.00 | AF29: 7.00 | AG29: 132,528.00 | AH29: 7
A30: MUD_29 | B30: 8042 | C30: 0.059722222 | D30: {=IFERROR(INDIRECT("'renta'!G$"&MATCH(T30,renta!$A:$A,0))*0.975-(G30*INDIRECT("'renta'!G$"&MATCH(F30,renta!$A:$A,0)))/B30-IFERROR((J30*INDIRECT("'renta'!G$"&MATCH(I30,renta!$A:$A,0)))/B30,0),)} -> -0.00042824969 | E30: =IFERROR( D30/C30/24*B30*2*(1+AI30),0) -> -4.8055591 | F30: EARTH | G30: =H30*0.95 -> 22919.7 | H30: 24126,00 | L30: 100.00% | M30: 1.149 | N30: 1 | O30: STEEL | P30: 30 | R30: {=INDIRECT("'renta'!G$"&MATCH(O30,renta!$A:$A,0))*P30} -> 1110 | S30: =SUM(R$2:R30) -> 7702.475 | T30: =IFERROR(LEFT(A30, FIND("_", A30) - 1),"") -> MUD | U30: =(E30-E29)/R30*1000 -> -0.068036425 | W30: =IFERROR(D30/V30*B30,) | Y30: 312 | Z30: 0.0013888889 | AA30: 1.61% | AB30: 403,992.00 | AC30: 360,000.00 | AF30: 7.00 | AG30: 134,664.00 | AH30: 7
... A43: MUD_42 | B43: 11872 | C43: 0.075 | D43: {=IFERROR(INDIRECT("'renta'!G$"&MATCH(T43,renta!$A:$A,0))*0.975-(G43*INDIRECT("'renta'!G$"&MATCH(F43,renta!$A:$A,0)))/B43-IFERROR((J43*INDIRECT("'renta'!G$"&MATCH(I43,renta!$A:$A,0)))/B43,0),)} -> -0.00042824969 | E43: =IFERROR( D43/C43/24*B43*2*(1+AI43),0) -> -5.6490893 | F43: EARTH | G43: =H43*0.95 -> 33835.2 | H43: 35616,00 | L43: 100.00% | M43: 1.696 | N43: 1 | O43: SCREWS | P43: 49 | R43: {=INDIRECT("'renta'!G$"&MATCH(O43,renta!$A:$A,0))*P43} -> 6501.4255 | S43: =SUM(R$2:R43) -> 49242.03 | T43: =IFERROR(LEFT(A43, FIND("_", A43) - 1),"") -> MUD | U43: =(E43-E42)/R43*1000 -> -0.0087057938 | W43: =IFERROR(D43/V43*B43,) | Y43: 284 | Z43: 0.0010416667 | AA43: 1.03% | AB43: 474,912.00 | AC43: 360,000.00 | AF43: 7.00 | AG43: 158,304.00 | AH43: 7
A44: MUD_43 | B44: 12159 | C44: 0.076041667 | D44: {=IFERROR(INDIRECT("'renta'!G$"&MATCH(T44,renta!$A:$A,0))*0.975-(G44*INDIRECT("'renta'!G$"&MATCH(F44,renta!$A:$A,0)))/B44-IFERROR((J44*INDIRECT("'renta'!G$"&MATCH(I44,renta!$A:$A,0)))/B44,0),)} -> -0.00042824969 | E44: =IFERROR( D44/C44/24*B44*2*(1+AI44),0) -> -5.7063978 | F44: EARTH | G44: =H44*0.95 -> 34653.15 | H44: 36477,00 | L44: 100.00% | M44: 1.737 | N44: 1 | O44: SCREWS | P44: 55 | R44: {=INDIRECT("'renta'!G$"&MATCH(O44,renta!$A:$A,0))*P44} -> 7297.5184 | S44: =SUM(R$2:R44) -> 56539.549 | T44: =IFERROR(LEFT(A44, FIND("_", A44) - 1),"") -> MUD | U44: =(E44-E43)/R44*1000 -> -0.007853155 | W44: =IFERROR(D44/V44*B44,) | Y44: 287 | Z44: 0.0010532407 | AA44: 0.01 | AB44: 479,664.00 | AC44: 360,000.00 | AF44: 7.00 | AG44: 159,888.00 | AH44: 7
A45: MUD_44 | B45: 12444 | C45: 0.077071759 | D45: {=IFERROR(INDIRECT("'renta'!G$"&MATCH(T45,renta!$A:$A,0))*0.975-(G45*INDIRECT("'renta'!G$"&MATCH(F45,renta!$A:$A,0)))/B45-IFERROR((J45*INDIRECT("'renta'!G$"&MATCH(I45,renta!$A:$A,0)))/B45,0),)} -> -0.00042824969 | E45: =IFERROR( D45/C45/24*B45*2*(1+AI45),0) -> -5.7620967 | F45: EARTH | G45: =H45*0.95 -> 35465.4 | H45: 37332,00 | L45: 100.00% | M45: 1.778 | N45: 1 | O45: SCREWS | P45: 62 | R45: {=INDIRECT("'renta'!G$"&MATCH(O45,renta!$A:$A,0))*P45} -> 8226.2935 | S45: =SUM(R$2:R45) -> 64765.842 | T45: =IFERROR(LEFT(A45, FIND("_", A45) - 1),"") -> MUD | U45: =(E45-E44)/R45*1000 -> -0.0067708377 | W45: =IFERROR(D45/V45*B45,) | Y45: 285 | Z45: 0.0010300926 | AA45: 0.98% | AB45: 484,344.00 | AC45: 360,000.00 | AF45: 7.00 | AG45: 161,448.00 | AH45: 7
A46: MUD_45 | B46: 12733 | C46: 0.078125 | D46: {=IFERROR(INDIRECT("'renta'!G$"&MATCH(T46,renta!$A:$A,0))*0.975-(G46*INDIRECT("'renta'!G$"&MATCH(F46,renta!$A:$A,0)))/B46-IFERROR((J46*INDIRECT("'renta'!G$"&MATCH(I46,renta!$A:$A,0)))/B46,0),)} -> -0.00042824969 | E46: =IFERROR( D46/C46/24*B46*2*(1+AI46),0) -> -5.8164302 | F46: EARTH | G46: =H46*0.95 -> 36289.05 | H46: 38199,00 | L46: 100.00% | M46: 1.819 | N46: 1 | O46: SCREWS | P46: 69 | R46: {=INDIRECT("'renta'!G$"&MATCH(O46,renta!$A:$A,0))*P46} -> 9155.0686 | S46: =SUM(R$2:R46) -> 73920.911 | T46: =IFERROR(LEFT(A46, FIND("_", A46) - 1),"") -> MUD | U46: =(E46-E45)/R46*1000 -> -0.0059348005 | W46: =IFERROR(D46/V46*B46,) | Y46: 289 | Z46: 0.0010416667 | AA46: 0.95% | AB46: 488,952.00 | AC46: 360,000.00 | AF46: 7.00 | AG46: 162,984.00 | AH46: 7
A47: MUD_46 | B47: 13023 | C47: 0.079166667 | D47: {=IFERROR(INDIRECT("'renta'!G$"&MATCH(T47,renta!$A:$A,0))*0.975-(G47*INDIRECT("'renta'!G$"&MATCH(F47,renta!$A:$A,0)))/B47-IFERROR((J47*INDIRECT("'renta'!G$"&MATCH(I47,renta!$A:$A,0)))/B47,0),)} -> -0.00042824969 | E47: =IFERROR( D47/C47/24*B47*2*(1+AI47),0) -> -5.8706271 | F47: EARTH | G47: =H47*0.95 -> 37115.55 | H47: 39069,00 | L47: 100.00% | M47: 1.861 | N47: 1 | O47: SCREWS | P47: 78 | R47: {=INDIRECT("'renta'!G$"&MATCH(O47,renta!$A:$A,0))*P47} -> 10349.208 | S47: =SUM(R$2:R47) -> 84270.119 | T47: =IFERROR(LEFT(A47, FIND("_", A47) - 1),"") -> MUD | U47: =(E47-E46)/R47*1000 -> -0.005236814 | W47: =IFERROR(D47/V47*B47,) | Y47: 290 | Z47: 0.0010416667 | AA47: 0.93% | AB47: 493,488.00 | AC47: 360,000.00 | AF47: 7.00 | AG47: 164,496.00 | AH47: 7
A48: MUD_47 | B48: 13314 | C48: 0.080208333 | D48: {=IFERROR(INDIRECT("'renta'!G$"&MATCH(T48,renta!$A:$A,0))*0.975-(G48*INDIRECT("'renta'!G$"&MATCH(F48,renta!$A:$A,0)))/B48-IFERROR((J48*INDIRECT("'renta'!G$"&MATCH(I48,renta!$A:$A,0)))/B48,0),)} -> -0.00042824969 | E48: =IFERROR( D48/C48/24*B48*2*(1+AI48),0) -> -5.9238612 | F48: EARTH | G48: =H48*0.95 -> 37944.9 | H48: 39942,00 | L48: 100.00% | M48: 1.902 | N48: 1 | O48: SCREWS | P48: 87 | R48: {=INDIRECT("'renta'!G$"&MATCH(O48,renta!$A:$A,0))*P48} -> 11543.347 | S48: =SUM(R$2:R48) -> 95813.466 | T48: =IFERROR(LEFT(A48, FIND("_", A48) - 1),"") -> MUD | U48: =(E48-E47)/R48*1000 -> -0.0046116693 | W48: =IFERROR(D48/V48*B48,) | Y48: 291 | Z48: 0.0010416667 | AA48: 0.9% | AB48: 497,952.00 | AC48: 360,000.00 | AF48: 7.00 | AG48: 165,984.00 | AH48: 7
A49: MUD_48 | B49: 13605 | C49: 0.08125 | D49: {=IFERROR(INDIRECT("'renta'!G$"&MATCH(T49,renta!$A:$A,0))*0.975-(G49*INDIRECT("'renta'!G$"&MATCH(F49,renta!$A:$A,0)))/B49-IFERROR((J49*INDIRECT("'renta'!G$"&MATCH(I49,renta!$A:$A,0)))/B49,0),)} -> -0.00042824969 | E49: =IFERROR( D49/C49/24*B49*2*(1+AI49),0) -> -5.9757303 | F49: EARTH | G49: =H49*0.95 -> 38774.25 | H49: 40815,00 | L49: 100.00% | M49: 1.944 | N49: 1 | O49: SCREWS | P49: 100 | R49: {=INDIRECT("'renta'!G$"&MATCH(O49,renta!$A:$A,0))*P49} -> 13268.215 | S49: =SUM(R$2:R49) -> 109081.68 | T49: =IFERROR(LEFT(A49, FIND("_", A49) - 1),"") -> MUD | U49: =(E49-E48)/R49*1000 -> -0.0039092766 | W49: =IFERROR(D49/V49*B49,) | Y49: 291 | Z49: 0.0010416667 | AA49: 0.88% | AB49: 502,344.00 | AC49: 360,000.00 | AF49: 7.00 | AG49: 167,448.00 | AH49: 7
A50: MUD_49 | B50: 13897 | C50: 0.082291667 | D50: {=IFERROR(INDIRECT("'renta'!G$"&MATCH(T50,renta!$A:$A,0))*0.975-(G50*INDIRECT("'renta'!G$"&MATCH(F50,renta!$A:$A,0)))/B50-IFERROR((J50*INDIRECT("'renta'!G$"&MATCH(I50,renta!$A:$A,0)))/B50,0),)} -> -0.00042824969 | E50: =IFERROR( D50/C50/24*B50*2*(1+AI50),0) -> -6.02672 | F50: EARTH | G50: =H50*0.95 -> 39606.45 | H50: 41691,00 | L50: 100.00% | M50: 1.986 | N50: 1 | O50: SCREWS | P50: 120 | R50: {=INDIRECT("'renta'!G$"&MATCH(O50,renta!$A:$A,0))*P50} -> 15921.858 | S50: =SUM(R$2:R50) -> 125003.54 | T50: =IFERROR(LEFT(A50, FIND("_", A50) - 1),"") -> MUD | U50: =(E50-E49)/R50*1000 -> -0.0032024937 | W50: =IFERROR(D50/V50*B50,) | Y50: 292 | Z50: 0.0010416667 | AA50: 0.85% | AB50: 506,624.81 | AC50: 360,000.00 | AF50: 7.00 | AG50: 168,874.94 | AH50: 7
A51: MUD_50 | B51: 14192 | C51: 0.083333333 | D51: {=IFERROR(INDIRECT("'renta'!G$"&MATCH(T51,renta!$A:$A,0))*0.975-(G51*INDIRECT("'renta'!G$"&MATCH(F51,renta!$A:$A,0)))/B51-IFERROR((J51*INDIRECT("'renta'!G$"&MATCH(I51,renta!$A:$A,0)))/B51,0),)} -> -0.00042824969 | E51: =IFERROR( D51/C51/24*B51*2*(1+AI51),0) -> -6.0777196 | F51: EARTH | G51: =H51*0.95 -> 40447.2 | H51: 42576,00 | L51: 100.00% | M51: 2.028 | N51: 1 | O51: SCREWS | P51: 150 | R51: {=INDIRECT("'renta'!G$"&MATCH(O51,renta!$A:$A,0))*P51} -> 19902.323 | S51: =SUM(R$2:R51) -> 144905.86 | T51: =IFERROR(LEFT(A51, FIND("_", A51) - 1),"") -> MUD | U51: =(E51-E50)/R51*1000 -> -0.0025624978 | W51: =IFERROR(D51/V51*B51,) | Y51: 295 | Z51: 0.0010416667 | AA51: 0.85% | AB51: 510,912.00 | AC51: 360,000.00 | AF51: 7.00 | AG51: 170,304.00 | AH51: 7
D52: {=IFERROR(INDIRECT("'renta'!G$"&MATCH(T52,renta!$A:$A,0))*0.975-(G52*INDIRECT("'renta'!G$"&MATCH(F52,renta!$A:$A,0)))/B52-IFERROR((J52*INDIRECT("'renta'!G$"&MATCH(I52,renta!$A:$A,0)))/B52,0),)} | E52: =IFERROR( D52/C52/24*B52*2*(1+AI52),0) -> 0 | G52: =H52*0.95 -> 0 | T52: =IFERROR(LEFT(A52, FIND("_", A52) - 1),"") | U52: =(E52-E51)/R52*1000 -> #DIV/0! | W52: =IFERROR(D52/V52*B52,)
...

Sheet prod
B3: k power prod | C3: fuel conso | D3: cout/kpower | F3: k prod | H3: cout/kpower
B4: 1 | C4: 0.03 | D4: =C4*renta!$G$18/B4 -> 7.2 | F4: 111 | G4: 0.02 | H4: =G4*renta!$G$29/F4 -> 4.2426368
B5: 1.3 | C5: 0.04 | D5: =C5*renta!$G$18/B5 -> 7.3846154
D6: =C6*renta!$G$18/B6 -> #DIV/0!
D7: =C7*renta!$G$18/B7 -> #DIV/0!
D8: =C8*renta!$G$18/B8 -> #DIV/0!
D9: =C9*renta!$G$18/B9 -> #DIV/0!
D10: =C10*renta!$G$18/B10 -> #DIV/0!
D11: =C11*renta!$G$18/B11 -> #DIV/0!
D12: =C12*renta!$G$18/B12 -> #DIV/0!
D13: =C13*renta!$G$18/B13 -> #DIV/0!
D14: =C14*renta!$G$18/B14 -> #DIV/0!
D15: =C15*renta!$G$18/B15 -> #DIV/0!
D16: =C16*renta!$G$18/B16 -> #DIV/0!
D17: =C17*renta!$G$18/B17 -> #DIV/0!
C20: kw/h | E20: prix | F20: kcoin/kw
B21: 6k/h | C21: 3 | E21: =8*renta!$G$20 -> 19368 | F21: =E21/C21/1000 -> 6.456
C22: 1.68 | E22: =3*renta!$G$26 -> 6750 | F22: =E22/C22/1000 -> 4.0178571
B23: 75.6

Sheet Feuille 1
G1: rapport | H1: min/item | I1: prix man | J1: prix man | K1: coin/earth | L1: coin/precédent | M1: gain de l'usine coin/h | N1: prix en coin/sand | O1: prix en coin/mud | Q1: pool
A2: mine | B2: 1 | C2: 11800 | G2: 1 | H2: =(60+41)/50500 -> 0.002 | I2: =0.00264 -> 0.00264 | J2: =0.00264 -> 0.00264 | K2: =J2 -> 0.00264 | L2: =K2 -> 0.00264 | M2: =J2/H2*60 -> 79.2 | Q2: 0xc356cd52364541379ad4d31a889b7031e758220a
A3: mud | B3: =C2/C3 -> 2.8710462 | C3: 4110 | D3: 12800 | G3: =11800/4110 -> 2.8710462 | H3: =30/4110 -> 0.0072992701 | I3: 0.00793 | J3: 0.00793 | K3: =G2*G3*$J$2 -> 0.007579562 | L3: =J2*G3 -> 0.007579562 | M3: =(J3-L3)/H3*60 -> 2.8806 | O3: 0.0194 | Q3: 0xb287ea5a5cd4f2b74571e30fdec96241aa5163d9
A4: clay | B4: =B3*D3/D4 -> 27.840448 | D4: 1320 | E4: 1310 | G4: =12800/1320 -> 9.6969697 | H4: =47/1320 -> 0.035606061 | I4: 0.0785 | J4: 0.0785 | K4: =K3*G4 -> 0.073498783 | L4: =J3*G4 -> 0.07689697 | M4: =(J4-L4)/H4*60 -> 2.7012766 | O4: =O3*D3/D4 -> 0.18812121 | Q4: 0x8b1a1b7b43a53904b0a05406c13399079e553501
A5: sand | B5: =B4*E4/E5 -> 80.156016 | E5: 455 | F5: 523 | G5: =1310/455 -> 2.8791209 | H5: =57/455 -> 0.12527473 | I5: 0.22 | J5: 0.22 | K5: =K4*G5 -> 0.21161188 | L5: =J4*G5 -> 0.22601099 | M5: =(J5-L5)/H5*60 -> -2.8789474 | N5: 0.25 | Q5: 0x6d8839a585f7877a5e218a217c07334980f04a4a
A6: copper | B6: =B5*F5/F6 -> 2328.9776 | C6: 4.77 | F6: 18 | G6: =513/18 -> 28.5 | H6: =104/18 -> 5.7777778 | I6: 6 | J6: 6 | K6: =K5*G6 -> 6.0309386 | L6: =J5*G6 -> 6.27 | M6: =(J6-L6)/H6*60 -> -2.8038462 | N6: =N5*G5/G6 -> 0.025255446 | Q6: 0xe9e419dbe8e0e056bb91989eb10f5fa62a0cb702
A7: steel | B7: =B6*C6/C7 -> 11109.223 | C7: 1 | D7: 3 | G7: =4.17 -> 4.17 | H7: =3*60+21 -> 201 | I7: 45 | J7: 45 | K7: =K6*G7 -> 25.149014 | L7: =J6*G7 -> 25.02 | M7: =(J7-L7)/H7*60 -> 5.9641791 | Q7: 0x70c063f17dacb35e4b3df06c8f36020416a44a3c
A8: screw | B8: =B7*D7/D8 -> 33327.669 | D8: 1 | G8: 2.67 | H8: =4*60+27 -> 267 | I8: 145 | J8: 145 | K8: =K7*G8 -> 67.147868 | L8: =J7*G8 -> 120.15 | M8: =(J8-L8)/H8*60 -> 5.5842697 | Q8: 0x0016c4c602cc1a96a9d35fe133a7e374d3cdc26d
O9: renta mines
A10: ceramic | G10: =1060/4 -> 265 | K10: =(G10*J4+G11*J15) -> 49.9525 | O10: =M2+3*M7+2*M8 -> 108.26108 | Q10: 0xfa3a564b27deb29781f80032df662a4406eebef6
G11: =10.6/4 -> 2.65 | O11: =6*M7+2*M8 -> 46.953614
A12: roc | G12: =17.7/2 -> 8.85 | K12: =G12*J6+G13*J17 -> 169.26
G13: =5.28/2 -> 2.64 | O13: renta Water
A14: water | B14: 1 | C14: 8 | G14: =152/30 -> 5.0666667 | H14: =60/12 -> 5 | I14: 1.85 | J14: 1.85 | K14: =J14 -> 1.85 | L14: 0.46 | M14: =J14/H14*60 -> 22.2 | O14: =M14+2*M15+3*M17+3*M18+3*M19+2*M20 -> 340.50955 | Q14: 0xe9c0995144a199241a5c46ccb7e7cd439af3ac75
A15: seawater 30 | B15: 7.92 | C15: 1 | G15: =152/30 -> 5.0666667 | H15: =(2*60+43)/30 -> 5.4333333 | I15: 11 | J15: 11 | K15: =K14*G15 -> 9.3733333 | L15: =J14*G15 -> 9.3733333 | M15: =(J15-L15)/H15*60 -> 17.96319 | O15: middle | Q15: 0xd1d6bb059c97295f7437ad423111047cbcddf4c6
A16: seawater 19 | B16: 7.92 | C16: 1 | G16: =60.8/10 -> 6.08 | H16: =(60*1+21)/10 -> 8.1 | I16: =I15 -> 11 | J16: =J15 -> 11 | K16: =K14*G16 -> 11.248 | L16: =J14*G16 -> 11.248 | M16: =(J16-L16)/H16*60 -> -1.837037 | O16: =6*M7+2*M8 -> 46.953614 | Q16: 0xd1d6bb059c97295f7437ad423111047cbcddf4c6
A17: alga | B17: 2 | G17: =27.2/8 -> 3.4 | H17: =(3*60+34)/8 -> 26.75 | I17: 44 | J17: 44 | K17: =K15*G17 -> 31.869333 | L17: =J15*G17 -> 37.4 | M17: =(J17-L17)/H17*60 -> 14.803738 | O17: all | P17: par 12h | Q17: 0xe63f8cefea9a17a259bb3b375929bd10d5e1cdfa
A18: oxy | G18: =12.8/5 -> 2.56 | H18: =(6*60+50)/5 -> 82 | I18: 127 | J18: 127 | K18: =K17*G18 -> 81.585493 | L18: =J17*G18 -> 112.64 | M18: =(J18-L18)/H18*60 -> 10.507317 | O18: =O10+O14+O16 -> 495.72424 | P18: =O18*60*12 -> 356921.45 | Q18: 0x4343846ebe54dcd40ba572275640230d533296e5
A19: gas | G19: =4.96/3 -> 1.6533333 | H19: =(3*60+12)/3 -> 64 | I19: 260 | J19: 260 | K19: =K18*G19 -> 134.88802 | L19: =J18*G19 -> 209.97333 | M19: =(J19-L19)/H19*60 -> 46.9 | Q19: 0x4782e36bbe6e9abca5357d3e43a090fa772de71b
A20: fuel | G20: 2.48 | H20: =(3*60+12) -> 192 | I20: 750 | J20: 750 | K20: =K19*G20 -> 334.52228 | L20: =J19*G20 -> 644.8 | M20: =(J20-L20)/H20*60 -> 32.875 | O20: 2,55 ou 2,48 | Q20: 0x0f8f4dcf1b6eb9f5c0e8fbb9cd6879aa3983c8bc
A21: oil | G21: 2.53 | H21: =5*60 -> 300 | I21: 1850 | J21: 1850 | K21: =K20*G21 -> 846.34137 | L21: =J20*G21 -> 1897.5 | M21: =(J21-L21)/H21*60 -> -9.5 | Q21: 0x6f363e6760876a4c66730fbbefccdd3014b6220c | V21: =192/2 -> 96
U22: =8*60 -> 480 | V22: =U22/(3.25) -> 147.69231
U23: =U22/H20 -> 2.5
U24: =H20/U22 -> 0.4
O25: fuel 10
